2022-11-01 03:41:32,257 ERROR root Message is too long
2023-01-20 22:11:19,354 ERROR asyncio Task exception was never retrieved
future: <Task finished coro=<Dispatcher._process_polling_updates() done, defined at C:\Users\Acer\AppData\Local\Programs\Python\Python37\lib\site-packages\aiogram\dispatcher\dispatcher.py:407> exception=NameError("name 'num' is not defined")>
Traceback (most recent call last):
  File "C:\Users\Acer\AppData\Local\Programs\Python\Python37\lib\site-packages\aiogram\dispatcher\dispatcher.py", line 415, in _process_polling_updates
    for responses in itertools.chain.from_iterable(await self.process_updates(updates, fast)):
  File "C:\Users\Acer\AppData\Local\Programs\Python\Python37\lib\site-packages\aiogram\dispatcher\dispatcher.py", line 235, in process_updates
    return await asyncio.gather(*tasks)
  File "C:\Users\Acer\AppData\Local\Programs\Python\Python37\lib\site-packages\aiogram\dispatcher\handler.py", line 117, in notify
    response = await handler_obj.handler(*args, **partial_data)
  File "C:\Users\Acer\AppData\Local\Programs\Python\Python37\lib\site-packages\aiogram\dispatcher\dispatcher.py", line 283, in process_update
    return await self.callback_query_handlers.notify(update.callback_query)
  File "C:\Users\Acer\AppData\Local\Programs\Python\Python37\lib\site-packages\aiogram\dispatcher\handler.py", line 117, in notify
    response = await handler_obj.handler(*args, **partial_data)
  File "C:/Users/Acer/PycharmProjects/USE_History_Bot/USE_History_Bot_git/main.py", line 133, in list_forward_call
    num += 1
NameError: name 'num' is not defined
